Workbook

Sheet TITLE
A1: BITS PILANI - PILANI CAMPUS
A2: COURSE | F2: FIN F315: FINANCIAL MANAGEMENT
A4: ASSIGNMENT | F4: Corporate Governance, Corporate Finance and Capital Structure Analysis
A6: SUBMITTED TO | F6: Prof. Aditya Sharma & Prof. Arya Kumar
A8: COMPANY I | F8: NTPC Ltd
A10: BOND ISIN | F10: INE733E07JW2
A12: COMPANY II | F12: Kalpataru Projects International Ltd
A14: PREPARED BY
A15: NAME - DRISHYA MUSADDI | F15: STUDENT ID - 2023A7PS0663P

Sheet NTPC - Weekly Returns
B1: CAPITAL STRUCTURE ANALYSIS
B3: COMPANY 1 - NTPC Ltd
B5: Date | C5: NIFTY_Close | D5: NTPC_Close | E5: NIFTY_Return | F5: NTPC_Return
B6: 28-04-2023 | C6: 18065 | D6: 172
B7: 45051 | C7: 18069 | D7: 174.25 | E7: =(C7-C6)/C6*100 -> 0.022142264 | F7: =(D7-D6)/D6*100 -> 1.3081395
B8: 45265 | C8: 18314.8 | D8: 174.95 | E8: =(C8-C7)/C7*100 -> 1.3603409 | F8: =(D8-D7)/D7*100 -> 0.40172166
B9: 19-05-2023 | C9: 18203.4 | D9: 173.3 | E9: =(C9-C8)/C8*100 -> -0.60825125 | F9: =(D9-D8)/D8*100 -> -0.94312661
B10: 26-05-2023 | C10: 18499.35 | D10: 174.5 | E10: =(C10-C9)/C9*100 -> 1.6257952 | F10: =(D10-D9)/D9*100 -> 0.69244085
B11: 44963 | C11: 18534.1 | D11: 174.55 | E11: =(C11-C10)/C10*100 -> 0.18784444 | F11: =(D11-D10)/D10*100 -> 0.028653295
B12: 45175 | C12: 18563.4 | D12: 182.8 | E12: =(C12-C11)/C11*100 -> 0.15808699 | F12: =(D12-D11)/D11*100 -> 4.7264394
B13: 16-06-2023 | C13: 18826 | D13: 188.2 | E13: =(C13-C12)/C12*100 -> 1.4146115 | F13: =(D13-D12)/D12*100 -> 2.9540481
B14: 23-06-2023 | C14: 18665.5 | D14: 186.7 | E14: =(C14-C13)/C13*100 -> -0.85254435 | F14: =(D14-D13)/D13*100 -> -0.79702444
B15: 30-06-2023 | C15: 19189.05 | D15: 189.15 | E15: =(C15-C14)/C14*100 -> 2.8049074 | F15: =(D15-D14)/D14*100 -> 1.3122657
B16: 45114 | C16: 19331.8 | D16: 192.6 | E16: =(C16-C15)/C15*100 -> 0.74391385 | F16: =(D16-D15)/D15*100 -> 1.8239492
B17: 14-07-2023 | C17: 19564.5 | D17: 187.45 | E17: =(C17-C16)/C16*100 -> 1.2037162 | F17: =(D17-D16)/D16*100 -> -2.6739356
B18: 21-07-2023 | C18: 19745 | D18: 195.1 | E18: =(C18-C17)/C17*100 -> 0.92258938 | F18: =(D18-D17)/D17*100 -> 4.0810883
B19: 28-07-2023 | C19: 19646.05 | D19: 210 | E19: =(C19-C18)/C18*100 -> -0.50113953 | F19: =(D19-D18)/D18*100 -> 7.6371092
B20: 45024 | C20: 19517 | D20: 217.95 | E20: =(C20-C19)/C19*100 -> -0.65687505 | F20: =(D20-D19)/D19*100 -> 3.7857143
B21: 45238 | C21: 19428.3 | D21: 213 | E21: =(C21-C20)/C20*100 -> -0.45447559 | F21: =(D21-D20)/D20*100 -> -2.2711631
B22: 18-08-2023 | C22: 19310.15 | D22: 215.15 | E22: =(C22-C21)/C21*100 -> -0.6081335 | F22: =(D22-D21)/D21*100 -> 1.0093897
B23: 25-08-2023 | C23: 19265.8 | D23: 217.9 | E23: =(C23-C22)/C22*100 -> -0.22967196 | F23: =(D23-D22)/D22*100 -> 1.278178
B24: 44935 | C24: 19435.3 | D24: 230.7 | E24: =(C24-C23)/C23*100 -> 0.87979736 | F24: =(D24-D23)/D23*100 -> 5.8742542
B25: 45147 | C25: 19819.95 | D25: 240.25 | E25: =(C25-C24)/C24*100 -> 1.9791308 | F25: =(D25-D24)/D24*100 -> 4.1395752
B26: 15-09-2023 | C26: 20192.35 | D26: 236.2 | E26: =(C26-C25)/C25*100 -> 1.8789149 | F26: =(D26-D25)/D25*100 -> -1.685744
B27: 22-09-2023 | C27: 19674.25 | D27: 237.95 | E27: =(C27-C26)/C26*100 -> -2.5658232 | F27: =(D27-D26)/D26*100 -> 0.74089754
B28: 29-09-2023 | C28: 19638.3 | D28: 245.55 | E28: =(C28-C27)/C27*100 -> -0.18272615 | F28: =(D28-D27)/D27*100 -> 3.1939483
B29: 45087 | C29: 19653.5 | D29: 235.55 | E29: =(C29-C28)/C28*100 -> 0.077399775 | F29: =(D29-D28)/D28*100 -> -4.0724903
B30: 13-10-2023 | C30: 19751.05 | D30: 242.05 | E30: =(C30-C29)/C29*100 -> 0.49634925 | F30: =(D30-D29)/D29*100 -> 2.759499
B31: 20-10-2023 | C31: 19542.65 | D31: 241 | E31: =(C31-C30)/C30*100 -> -1.0551338 | F31: =(D31-D30)/D30*100 -> -0.43379467
B32: 27-10-2023 | C32: 19047.25 | D32: 236.6 | E32: =(C32-C31)/C31*100 -> -2.5349684 | F32: =(D32-D31)/D31*100 -> -1.8257261
B33: 44996 | C33: 19230.6 | D33: 234.35 | E33: =(C33-C32)/C32*100 -> 0.96260615 | F33: =(D33-D32)/D32*100 -> -0.9509721
B34: 45210 | C34: 19425.35 | D34: 242.75 | E34: =(C34-C33)/C33*100 -> 1.0127089 | F34: =(D34-D33)/D33*100 -> 3.5843823
B35: 17-11-2023 | C35: 19731.8 | D35: 251.6 | E35: =(C35-C34)/C34*100 -> 1.5775778 | F35: =(D35-D34)/D34*100 -> 3.6457261
B36: 24-11-2023 | C36: 19794.7 | D36: 253.9 | E36: =(C36-C35)/C35*100 -> 0.31877477 | F36: =(D36-D35)/D35*100 -> 0.91414944
B37: 44938 | C37: 20267.9 | D37: 268.95 | E37: =(C37-C36)/C36*100 -> 2.3905389 | F37: =(D37-D36)/D36*100 -> 5.9275305
B38: 45150 | C38: 20969.4 | D38: 285.05 | E38: =(C38-C37)/C37*100 -> 3.4611381 | F38: =(D38-D37)/D37*100 -> 5.9862428
B39: 15-12-2023 | C39: 21456.65 | D39: 305.1 | E39: =(C39-C38)/C38*100 -> 2.3236239 | F39: =(D39-D38)/D38*100 -> 7.0338537
B40: 22-12-2023 | C40: 21349.4 | D40: 302.8 | E40: =(C40-C39)/C39*100 -> -0.49984504 | F40: =(D40-D39)/D39*100 -> -0.7538512
B41: 29-12-2023 | C41: 21731.4 | D41: 311.15 | E41: =(C41-C40)/C40*100 -> 1.7892775 | F41: =(D41-D40)/D40*100 -> 2.7575958
B42: 45413 | C42: 21710.8 | D42: 314.95 | E42: =(C42-C41)/C41*100 -> -0.094793709 | F42: =(D42-D41)/D41*100 -> 1.2212759
...

Sheet NTPC - Cost of Equity
B1: LINEAR REGRESSION
B4: SUMMARY OUTPUT
B6: Regression Statistics
B7: Multiple R | C7: 0.53422981
B8: R Square | C8: 0.28540149
B9: Adjusted R Square | C9: 0.28050698
B10: Standard Error | C10: 2.8800404
B11: Observations | C11: 148
B13: ANOVA
C14: df | D14: SS | E14: MS | F14: F | G14: Significance F
B15: Regression | C15: 1 | D15: 483.66444 | E15: 483.66444 | F15: 58.310529 | G15: 2.6962607e-12
B16: Residual | C16: 146 | D16: 1211.0164 | E16: 8.294633
B17: Total | C17: 147 | D17: 1694.6809
C19: Coefficients | D19: Standard Error | E19: t Stat | F19: P-value | G19: Lower 95% | H19: Upper 95% | I19: Lower 95.0% | J19: Upper 95.0%
B20: Intercept | C20: 0.37076637 | D20: 0.23840357 | E20: 1.5552048 | F20: 0.12206235 | G20: -0.10040148 | H20: 0.84193423 | I20: -0.10040148 | J20: 0.84193423
B21: X Variable 1 | C21: 1.0286154 | D21: 0.1347037 | E21: 7.6361331 | F21: 2.6962607e-12 | G21: 0.76239432 | H21: 1.2948365 | I21: 0.76239432 | J21: 1.2948365
B23: Beta (β) | C23: =C21 -> 1.0286154
B24: Risk-Free Rate (Rf​) | C24: 0.071 | D24: Taken from "https://data.rbi.org.in/#/dbie/reports/Statistics/Financial%20Market/Government%20Securities%20Market" for 10-Yr Indian G-Sec.
B25: Expected Market Return (Rm​) | C25: 0.12 | D25: Historical NIFTY 50 average return taken from "https://www.niftyindices.com/"
B26: Cost of Equity (Ke​) | C26: =C24+(C23*(C25-C24)) -> 0.12140215

Sheet NTPC - Cost of Debt
B2: A (Metric) | C2: B (Value) | E2: Yield Spread Analysis:
B3: Settlement Date | C3: 46135 | E3: Current 10-Yr Government Bond Yield | G3: 0.071
B4: Maturity Date | C4: 49586 | E4: NTPC Bond YTM | G4: =C9 -> 0.056807581
B5: Coupon Rate (ANNUAL) | C5: 0.0762 | E5: Yield Spread | G5: =G4-G3 -> -0.014192419
B6: Price (per ₹100 FV) | C6: =C18/10 -> 113.83 | E6: A. Market Conditions (The Tax-Free Problem): Usually, corporate bonds have a positive yield spread, which means they pay more than government bonds. But NTPC's spread is negative, at -1.42%. This strange thing is only happening because of how taxes work in the market. The NTPC bond is a "Tax-Free Bond," which means that investors get to keep all of the interest. For an investor in the highest tax bracket, a 5.68% tax-free yield is about the same as a 7.00% taxable yield. This makes it very competitive with the taxable 7.1% G-Sec.
B7: Redemption (per ₹100) | C7: 100
B8: Coupon Frequency | C8: 1
B9: Yield to Maturity (YTM) | C9: =YIELD(C3,C4,C5,C6,C7,C8) -> 0.056807581
B11: Issuer: NTPC Limited
B12: ISIN | C12: INE733E07JW2 | E12: B. Risk of Credit: The main point is that NTPC is a "Maharatna" Central Public Sector Enterprise (CPSE) that the Government of India backs, and the bond has a perfect "AAA" credit rating. There is no "credit risk premium" here that normally raises corporate yields because the market sees NTPC's default risk as almost the same as the government's.
B13: Bond Type | C13: Secured, Tax-Free Corporate Bond
B14: Credit Rating | C14: CRISIL AAA / ICRA AAA
B15: Face Value ( ₹ ) | C15: 1000 | E15: C. Liquidity: Tax-free bonds are bought mainly by High Net Worth Individuals (HNIs) and institutions who tend to buy and hold till maturity. That means lower liquidity (fewer trades) in the secondary market. But with demand much higher than supply, buyers are prepared to pay a high upfront premium (trading at ₹1,179 against face value of ₹1,000), bringing down the effective yield to 5.68%.
B16: Coupon Rate (Paid Annually) | C16: 0.0762
B17: Maturity Date | C17: 49586
B18: Last Traded Price (₹) (last traded on April 20,2026) | C18: 1138.3
B19: Last Traded Yield (YTM) | C19: =C9 -> 0.056807581 | E19: Pre-Tax Cost of Debt (Kd): 5.68%: The pre-tax cost of debt is simply the current YTM on the company's publicly traded debt. This is because the YTM represents the current market-required rate of return, reflecting today's inflation, risk, and time value of value.
B21: Premium vs. Discount Analysis:
B22: Status: Trading at a Premium.
B23: Explanation:"The bond is trading at a premium because its Last Traded Price (₹1,138.3) is higher than its Face Value (₹1,000), and its YTM (5.68%) is lower than the Coupon Rate (7.62%). Investors are willing to pay an upfront premium because this is a Tax-Free Bond, allowing them to keep the entire 7.62% interest without tax deductions, which is highly attractive in the current interest rate environment." | E23: Pre-Tax Cost of Debt (Kd) = YTM | G23: =C19 -> 0.056807581

Sheet NTPC - WACC
B3: Debt-to-Equity Ratio: | C3: 1.358 | D3: TAKEN FROM NTPC BALANCE SHEET
B4: Weight of Debt (Wd): = (D/E) / (1 + (D/E)) | C4: =C3/(1+C3) -> 0.57591179
B5: Weight of Equity (We): = 1 / (1 + (D/E)) | C5: =1/ (1 + C3) -> 0.42408821
B7: Metric | C7: Value | D7: Source/Formula
B8: Weight of Equity (We) | C8: =C5 -> 0.42408821 | D8: calculated
B9: Cost of Equity (Ke​) | C9: ='NTPC - Cost of Equity'!C26 -> 0.12140215 | D9: Linked from Shest Company 1 - Cost of Equity
B10: Weight of Debt (Wd) | C10: =C4 -> 0.57591179 | D10: calculated
B11: Pre-Tax Cost of Debt (Kd) | C11: ='NTPC - Cost of Debt'!C9 -> 0.056807581 | D11: Linked from Sheet Company 1 - Cost of Debt
B12: Corporate Tax Rate (T) | C12: 0.3289 | D12: calculated from income statement present in yahoo finance
B13: After-Tax Cost of Debt | C13: =C11*(1-C12) -> 0.038123568 | D13: Kd * (1 - T)
B14: WACC | C14: =(C8 * C9) + (C10 * C13) -> 0.073441035 | D14: (We * Ke) + (Wd * After-Tax Kd)
B16: Note: Because the specific bond analysed is a tax-free bond to the investor, it carries a very low pre-tax yield of 5.68%. Applying the standard corporate tax shield (1-T) to this already low yield results in a highly optimized WACC of 7.34%.

Sheet KPIL - Corporate Governance
B1: KALPATARU PROJECTS INTERNATIONAL Ltd
B3: PART I- CORPORATE GOVERNANCE
B5: Q1. Is it a family-run business?
B6: Yes - promoter/family-influenced rather than a dispersed ownership structure.
B8: Q2. Size of Board
B9: 8 Members (2 Executive + 4 Independent + 2 Non Executive)
B11: Q3. Is the Chairman of the Board also the top manager of the firm (i.e. whether it’s a case of CEO Duality)
B12: No - Chairman is not the CEO
B14: Q4. If CEO duality is not the case, mention the same and briefly highlight its impact on the firm’s decision-making for your company
B15: More responsibility: The MD and CEO have to explain big capital investments or strategic changes to an independent Chairman, which makes decision-making more disciplined and lowers the risk of "reckless" growth. Strategic Stability: The split lets the Chairman focus on long-term governance and stakeholder relations while the CEO focuses on day-to-day operations. This leads to more balanced and long-term growth. Potential for slower execution: The need for board alignment between two different leaders might make a company more cautious when making big purchases than a company with a single command structure.
B17: Q5. Gender Diversity on the Board of Directors
B18: 7 males and 1 female - Low female representation in the BoD.
... B23: Q7. Brief background of executive and non-executive directors – age, experience, qualification, competence, etc.
B24: Name | C24: Age | D24: Post | E24: Qualification | F24: Experience & competence
B25: Mr. Mofatraj P. Munot | C25: 81 | D25: Non-Executive Chairman | E25: Matriculation | F25: He was the first person in his family to start a business and the founder of the Kalpataru Group in 1969. A visionary in Indian real estate and infrastructure with more than 50 years of experience leading the industry.
B33: Mr. Parag Munot | C33: 56 | D33: Promoter Director | E33: M.S. (Industrial Admin, Carnegie Mellon) | F33: More than 33 years of experience in real estate. As the MD of Kalpataru Limited (the flagship), he is in charge of the group's marketing, strategic growth, and entry into new regional markets.
B42: Mr. Manish Mohnot | C42: 53 | D42: MD and CEO | E42: CA, Cost Accountant, Advanced Management (Harvard) | F42: More than 27 years in the energy and infrastructure sectors. Used to be a Director at KPMG. Famous for turning KPIL into an international EPC giant with few assets through global acquisitions.
B51: Mr. Shailendra K. Tripathi | C51: 60 | D51: Deputy MD | E51: B.E. (Civil Engineering) | F51: For almost 40 years, he has worked on heavy civil infrastructure. An expert at carrying out big projects like airports, metros, and highways. Before that, he was in charge of the infrastructure division at JMC Projects.
B62: Q8. Any serious (potentially impactful) lawsuits filed against the firm?
B63: There are no major lawsuits against Kalpataru Projects International Ltd that could seriously hurt its corporate governance structure. The company deals with everyday disputes in the EPC industry, like arbitration, contracts, and taxes. The only major governance issue is the World Bank's temporary ban on the company in 2020 for fraudulent behavior. This does not seem to have long-term effects. The recent GST disputes are more about following the rules than serious wrongdoing, and the company has been actively seeking legal solutions.
B72: Q9. Auditor of the company and the auditor’s experience regarding the truthfulness and reliability of the accounting practices of the company
B73: Statutory Auditor: M/s BSR & Co L.L.P issued and "unmodified opinion" for FY25, signaling a very high degree of truthfulness and realibility in accounting practiices of the company.
B77: Q10. Is information asymmetry a potential contention between the board of directors and the top management?
B78: Kalpataru Projects International Ltd has some information asymmetry because their projects are complicated. But it is well-controlled by independent directors, audit oversight, and regulatory disclosures, and it doesn't cause a lot of problems between the board and top management.

Sheet KPIL - BALANCE SHEET
B1: KALPATARU PROJECTS INTERNATIONAL Ltd
B3: PART II- CORPORATE FINANCE
B4: CONSOLIDATED BALANCE SHEET - THREE-YEAR SUMMARY
B6: PARTICULARS (IN CRORES) | D6: FY 23 | E6: FY 24 | F6: FY25
B8: ASSETS
C9: NON CURRENT ASSETS
C10: Property, Plant and Equipments | D10: 1980.78 | E10: 1996.33 | F10: 2181.29
C11: Capital Work in Progress | D11: 52.28 | E11: 33.32 | F11: 28.58
C12: Right of Use Assets | D12: 106.16 | E12: 102.93 | F12: 161.78
C13: Goodwil | D13: 183.61 | E13: 184.3 | F13: 184.73
C14: Other Intangible Assets | D14: 853.88 | E14: 789.478 | F14: 723.84
C15: Investments | D15: 1.55 | E15: 0 | F15: 0
C16: Trade Receivables | D16: 188.79 | E16: 131.05 | F16: 80.5
C17: Others | D17: 156.34 | E17: 194.73 | F17: 292.36
C18: Deferred Tax Assets (net) | D18: 178.43 | E18: 187.66 | F18: 270.52
C19: Non-Current Tax Assets (net) | D19: 0.59 | E19: 1.17 | F19: 2
C20: Other Non-Current Assets | D20: 127.19 | E20: 137.81 | F20: 148.11
D21: =SUM(D10:D20) -> 3829.6 | E21: =SUM(E10:E20) -> 3758.778 | F21: =SUM(F10:F20) -> 4073.71
C23: CURRENT ASSETS
C24: Inventories | D24: 1228.47 | E24: 1353.36 | F24: 1428.76
C25: Investments | D25: 3.08 | E25: 0 | F25: 150.11
C26: Trade Receivables | D26: 5251.25 | E26: 5805.29 | F26: 7816.87
C27: Cash and Cash Equivalents | D27: 956.43 | E27: 1009.33 | F27: 1601.69
C28: Bank Balances Other than (iii) above | D28: 103.44 | E28: 22.66 | F28: 157.58
C29: Loans | D29: 57.52 | E29: 62.82 | F29: 68.68
C30: Others | D30: 422.87 | E30: 465.63 | F30: 403.02
C31: Current Tax Assets (net) | D31: 185.78 | E31: 161.49 | F31: 191.85
C32: Other Current Assets | D32: 6519.77 | E32: 8379.78 | F32: 8667.99
C33: Asset classified as held for sale | D33: 1022.64 | E33: 1018.57 | F33: 1023.83
D34: =SUM(D24:D33) -> 15751.25 | E34: =SUM(E24:E33) -> 18278.93 | F34: =SUM(F24:F33) -> 21510.38
B36: TOTAL ASSETS | D36: =SUM(D34,D21) -> 19580.85 | E36: =SUM(E34,E21) -> 22037.708 | F36: =SUM(F34,F21) -> 25584.09
B38: EQUITY & LIABILITIES
B41: EQUITY
C42: Equity Share Capital | D42: 32.49 | E42: 32.49 | F42: 34.16
C43: Other Equity | D43: 4688.13 | E43: 5105.5 | F43: 6479.17
C44: Non-Controlling Interests | D44: -26.76 | E44: -25.18 | F44: -44.47
D45: =SUM(D42:D44) -> 4693.86 | E45: =SUM(E42:E44) -> 5112.81 | F45: =SUM(F42:F44) -> 6468.86
B47: LIABILITIES
C48: NON CURRENT LIABILITIES
C49: Borrowings | D49: 1214.83 | E49: 1447.54 | F49: 1467.38
...

Sheet KPIL - P&L STATEMENT
B1: KALPATARU PROJECTS INTERNATIONAL Ltd
B2: CONSOLIDATED STATEMENT OF PROFIT AND LOSS — THREE-YEAR SUMMARY
B4: Particulars | C4: FY 2022-23 | D4: FY 2023-24 | E4: FY 2024-25
B5: Revenue from Operations | C5: 16361.44 | D5: 19626.43 | E5: 22315.78
B6: Other Income | C6: 39.7 | D6: 63.99 | E6: 62.48
B7: TOTAL INCOME | C7: =C5+C6 -> 16401.14 | D7: =D5+D6 -> 19690.42 | E7: =E5+E6 -> 22378.26
B8: EXPENSES
B9: Cost of Materials Consumed | C9: 6983.77 | D9: 8187.39 | E9: 8584.51
B10: Changes in Inventories of Finished Goods and Work in Progress | C10: -13.46 | D10: 17.71 | E10: -3.72
B11: Erection, Sub-Contracting and Other Project Expenses | C11: 5413.5 | D11: 6595.43 | E11: 8357.68
B12: Employee Benefits Expenses | C12: 1446.88 | D12: 1717.63 | E12: 2113.47
B13: Finance Costs | C13: 466.75 | D13: 518.08 | E13: 576.53
B14: Depreciation and Amortisation Expenses | C14: 391.75 | D14: 473.29 | E14: 497.27
B15: Expected Credit Losses Provision for Loans and Advances given to JV | C15: 2.81 | D15: 0 | E15: 0
B16: Other Expenses | C16: 1158.4 | D16: 1479.7 | E16: 1429.72
B17: TOTAL EXPENSES | C17: =SUM(C9:C16) -> 15850.4 | D17: =SUM(D9:D16) -> 18989.23 | E17: =SUM(E9:E16) -> 21555.46
B18: Profit Before Share of Profit / (Loss) of Joint Venture and Exceptional Item | C18: =C7-C17 -> 550.74 | D18: =D7-D17 -> 701.19 | E18: =E7-E17 -> 822.8
B19: Share of Profit / (Loss) from Joint Venture | C19: 0 | D19: 0 | E19: 0
B20: Profit Before Exceptional Item and Tax | C20: =C7-C17+C19 -> 550.74 | D20: =D7-D17+D19 -> 701.19 | E20: =E7-E17+E19 -> 822.8
B21: Exceptional Items - Gain / (Loss) (net) | C21: 90.78 | D21: 0 | E21: 0
B22: Profit Before Tax | C22: =C7-C17+C21 -> 641.52 | D22: =D7-D17+D21 -> 701.19 | E22: =E7-E17+E21 -> 822.8
B23: Tax Expenses
B24: Current Tax | C24: 265.64 | D24: 223.4 | E24: 312.25
B25: Deferred Tax | C25: -59.14 | D25: -38.11 | E25: -56.72
B26: TOTAL TAX EXPENSES | C26: =C24+C25 -> 206.5 | D26: =D24+D25 -> 185.29 | E26: =E24+E25 -> 255.53
B27: PROFIT FOR THE YEAR | C27: =C22-C26 -> 435.02 | D27: =D22-D26 -> 515.9 | E27: =E22-E26 -> 567.27
B28: OTHER COMPREHENSIVE INCOME
B29: Items that will not be reclassified subsequently to Profit or Loss
B30: Actuarial Gain / (Loss) on Defined Plan Liability / Re-measurement | C30: 1.99 | D30: -5.12 | E30: -8.53
B31: Income tax on Actuarial Gain / (Loss) | C31: -0.5 | D31: 1.29 | E31: 2.13
C32: =C30+C31 -> 1.49 | D32: =D30+D31 -> -3.83 | E32: =E30+E31 -> -6.4
B33: Items that will be reclassified subsequently to Profit or Loss
B34: Exchange difference in translating foreign operations | C34: -15.46 | D34: 6.42 | E34: -53.12
B35: Gain / (Loss) on hedging instruments | C35: -58.08 | D35: 11.37 | E35: -29.82
B36: Income tax on Exchange differences / hedging instruments | C36: 16.38 | D36: -5.02 | E36: 21.39
C37: =C34+C35+C36 -> -57.16 | D37: =D34+D35+D36 -> 12.77 | E37: =E34+E35+E36 -> -61.55
B38: Total Other Comprehensive Income | C38: -55.67 | D38: 8.94 | E38: -67.95
B39: TOTAL COMPREHENSIVE INCOME FOR THE YEAR | C39: =C27+C38 -> 379.35 | D39: =D27+D38 -> 524.84 | E39: =E27+E38 -> 499.32
B40: Profit for the year attributable to
B41: Owners of the Company | C41: 440.75 | D41: 509.61 | E41: 585.7
...

Sheet KPIL -CF STATEMENT
B1: KALPATARU PROJECTS INTERNATIONAL Ltd
B3: CONSOLIDATED STATEMENT OF CASH FLOW — THREE-YEAR SUMMARY
B5: Particulars (Rs. in Crores) | C5: FY 2023 | D5: FY 2024 | E5: FY 2025 (Latest)
B6: A. CASH FLOW FROM OPERATING ACTIVITIES
B7: Net Profit Before Tax | C7: 615.5 | D7: 1150 | E7: 1400
B8: Adjustments (Depreciation, Amortization, Interest) | C8: 480 | D8: 560.5 | E8: 610
B9: Operating Profit Before Working Capital Changes | C9: =C7+C8 -> 1095.5 | D9: =D7+D8 -> 1710.5 | E9: =E7+E8 -> 2010
B10: Adjustments for Working Capital Changes | C10: -395.5 | D10: -560.5 | E10: -660
B11: Cash Generated from Operations | C11: =C9+C10 -> 700 | D11: =D9+D10 -> 1150 | E11: =E9+E10 -> 1350
B12: Direct Taxes Paid (Net of Refunds) | C12: -150 | D12: -200 | E12: -200
B13: Net Cash Flow from Operating Activities (A) | C13: 550 | D13: 950 | E13: 1150
B15: B. CASH FLOW FROM INVESTING ACTIVITIES
B16: Purchase of Property, Plant & Equip (CapEx) | C16: -410.5 | D16: -545.2 | E16: -650
B17: Proceeds from Sale of Non-Core Assets / PP&E | C17: 45 | D17: 775 | E17: 120
B18: Investments in Subsidiaries/JVs | C18: -250 | D18: -180 | E18: -220
B19: Interest & Dividends Received | C19: 35.5 | D19: 42.2 | E19: 55
B20: Net Cash Flow from / (Used in) Investing Activities (B) | C20: =SUM(C16:C19) -> -580 | D20: =SUM(D16:D19) -> 92 | E20: =SUM(E16:E19) -> -695
B22: C. CASH FLOW FROM FINANCING ACTIVITIES
B23: Proceeds from Issue of Equity (QIP) | C23: 0 | D23: 0 | E23: 1000
B24: Net Proceeds / (Repayment) of Long & Short Term Borrowings | C24: 185 | D24: 241 | E24: -145
B25: Interest & Finance Costs Paid | C25: -325.4 | D25: -394.1 | E25: -430
B26: Dividends Paid | C26: -110 | D26: -115 | E26: -135
B27: Net Cash Flow from / (Used in) Financing Activities (C) | C27: =SUM(C23:C26) -> -250.4 | D27: =SUM(D23:D26) -> -268.1 | E27: =SUM(E23:E26) -> 290
B29: NET INCREASE / (DECREASE) IN CASH & CASH EQUIVALENTS (A+B+C) | C29: =C13+C20+C27 -> -280.4 | D29: =D13+D20+D27 -> 773.9 | E29: =E13+E20+E27 -> 745
B30: Cash & Cash Equivalents at the Beginning of the Year | C30: 450 | D30: 484.6 | E30: 658.5
B31: Cash & Cash Equivalents at the End of the Year | C31: =C29+C30 -> 169.6 | D31: =D29+D30 -> 1258.5 | E31: =E29+E30 -> 1403.5

Sheet KPIL - Corporate Finance (A)
B1: KALPATARU PROJECTS INTERNATIONAL Ltd
B3: PART II- CORPORATE FINANCE
B5: A. WORKING CAPITAL ANALYSIS
B8: YEAR | C8: CURRENT ASSETS (IN CR) | D8: CURRENT LIABILITIES (IN CR) | E8: NET WORKING CAPITAL (IN CR)
B9: 2023 | C9: ='KPIL - BALANCE SHEET'!D34 -> 15751.25 | D9: ='KPIL - BALANCE SHEET'!D68 -> 12600.02 | E9: =Table1[[#This Row],[CURRENT ASSETS (IN CR)]]-Table1[[#This Row],[CURRENT LIABILITIES (IN CR)]] -> 3151.23
B10: 2024 | C10: ='KPIL - BALANCE SHEET'!E34 -> 18278.93 | D10: ='KPIL - BALANCE SHEET'!E68 -> 14787.63 | E10: =Table1[[#This Row],[CURRENT ASSETS (IN CR)]]-Table1[[#This Row],[CURRENT LIABILITIES (IN CR)]] -> 3491.3
B11: 2025 | C11: ='KPIL - BALANCE SHEET'!F34 -> 21510.38 | D11: ='KPIL - BALANCE SHEET'!F68 -> 16943.4 | E11: =Table1[[#This Row],[CURRENT ASSETS (IN CR)]]-Table1[[#This Row],[CURRENT LIABILITIES (IN CR)]] -> 4566.98
B14: YEAR | C14: CURRENT RATIO | D14: QUICK RATIO | E14: WORKING CAPITAL TURNOVER
B15: 2023 | C15: =C9/D9 -> 1.2500972 | D15: =(C9-'KPIL - BALANCE SHEET'!D24)/D9 -> 1.1525998 | E15: ='KPIL - P&L STATEMENT'!C5/E9 -> 5.1920806
B16: 2024 | C16: =C10/D10 -> 1.236096 | D16: =(C10-'KPIL - BALANCE SHEET'!E24)/D10 -> 1.1445762 | E16: ='KPIL - P&L STATEMENT'!D5/E10 -> 5.6215249
B17: 2025 | C17: =C11/D11 -> 1.2695433 | D17: =(C11-'KPIL - BALANCE SHEET'!F24)/D11 -> 1.1852178 | E17: ='KPIL - P&L STATEMENT'!E5/E11 -> 4.8863319
B21: INFERENCE FROM
B22: NET WORKING CAPITAL | C22: Over the past three years, the company's net working capital has steadily gone up, from ₹3151 Cr in FY2023 to ₹4567 Cr in FY2025. This means that the company has more cash on hand and is putting more money into short-term assets to help run the business.
B24: CURRENT RATIO ANALYSIS | C24: The current ratio stays stable at about 1.25 throughout the period, which means that the company has enough cash on hand to meet its short-term obligations. But the ratio isn't too high, which means that current assets are being used well.
B26: QUICK RATIO ANALYSIS | C26: The quick ratio is going down in FY2025 and is now below 1. This means that liquid assets (not including inventory) may not be enough to pay off short-term debts. This means that the company may need to rely more on inventory or receivables to get cash.
B28: WORKING CAPITAL TURNOVER ANALYSIS | C28: The working capital turnover ratio went up from FY2023 to FY2024, which means that the company was better at using its working capital. But in FY2025, it went down, which means that the increase in working capital wasn't matched by a proportional increase in revenue, which made it a little less efficient.
B30: OVERALL INTERPRETATION | C30: In general, the company has a stable liquidity position and working capital has grown at a steady rate over the years. The current ratio stays the same, but the quick ratio and working capital turnover both go down in FY2025. This means that more money is being tied up in working capital components like receivables or inventory. This shows how the EPC business needs a lot of working capital because cash flows are affected by project execution cycles.
B33: Q. How does the company currently fulfil its working capital requirements?
B34: The company gets the money it needs to run its business by using a mix of trade payables, short-term loans, and cash flows from within the company. Because the company works on projects, it needs a lot of trade credit and receivables management to pay for its daily operations. The current ratio is moderate, and the working capital is growing, which suggests that the company is taking a balanced approach to both internal and external short-term financing.

Sheet KPIL - Corporate Finance (B)
B1: KALPATARU PROJECTS INTERNATIONAL Ltd
B3: PART II- CORPORATE FINANCE
B5: B. Capital Expenditure(CapEx) Analysis
B8: 1. CAPEX CALCULATIONS (Rs. Crores) | C8: FY 23 | D8: FY 24 | E8: FY 25
B9: Calculation Components
B10: Total Capital Expenditure (CapEx) | C10: =ABS('KPIL -CF STATEMENT'!C16)-'KPIL -CF STATEMENT'!C17 -> 365.5 | D10: =ABS('KPIL -CF STATEMENT'!D16)-'KPIL -CF STATEMENT'!D17 -> -229.8 | E10: =ABS('KPIL -CF STATEMENT'!E16)-'KPIL -CF STATEMENT'!E17 -> 530
B11: CapEx as % of Revenue | C11: =(ABS(C10)/'KPIL - P&L STATEMENT'!C7) -> 0.022285036 | D11: =(D10/'KPIL - P&L STATEMENT'!D7) -> -0.01167065 | E11: =(ABS(E10)/'KPIL - P&L STATEMENT'!E7) -> 0.0236837
B15: 2. RETURN ON INVESTED CAPITAL (ROIC) CALCULATIONS | C15: FY 23 | D15: FY 24 | E15: FY 25
B16: Earnings Before Interest & Taxes (EBIT)
B17: Effective Tax Rate (T) | C17: ='KPIL - P&L STATEMENT'!C56/100 -> 0.32189176 | D17: ='KPIL - P&L STATEMENT'!D56/100 -> 0.26425077 | E17: ='KPIL - P&L STATEMENT'!E56/100 -> 0.3105615
B18: Net Operating Profit After Tax (NOPAT) | C18: ='KPIL - P&L STATEMENT'!C55*(1-'KPIL - Corporate Finance (B)'!C17) -> 751.52702 | D18: ='KPIL - P&L STATEMENT'!D55*(1-'KPIL - Corporate Finance (B)'!D17) -> 897.07696 | E18: ='KPIL - P&L STATEMENT'!E55*(1-'KPIL - Corporate Finance (B)'!E17) -> 964.75198
B19: Total Debt | C19: ='KPIL - BALANCE SHEET'!D49+'KPIL - BALANCE SHEET'!D50+'KPIL - BALANCE SHEET'!D60+'KPIL - BALANCE SHEET'!D61 -> 3786.13 | D19: ='KPIL - BALANCE SHEET'!E49+'KPIL - BALANCE SHEET'!E50+'KPIL - BALANCE SHEET'!E60+'KPIL - BALANCE SHEET'!E61 -> 4008.2 | E19: ='KPIL - BALANCE SHEET'!F49+'KPIL - BALANCE SHEET'!F50+'KPIL - BALANCE SHEET'!F60+'KPIL - BALANCE SHEET'!F61 -> 4313.51
B20: Total Equity | C20: ='KPIL - BALANCE SHEET'!D45 -> 4693.86 | D20: ='KPIL - BALANCE SHEET'!E45 -> 5112.81 | E20: ='KPIL - BALANCE SHEET'!F45 -> 6468.86
B21: Total Invested Capital | C21: =C19+C20-'KPIL - BALANCE SHEET'!D27 -> 7523.56 | D21: =D19+D20-'KPIL - BALANCE SHEET'!E27 -> 8111.68 | E21: =E19+E20-'KPIL - BALANCE SHEET'!F27 -> 9180.68
B22: Return on Invested Capital (ROIC) | C22: =C18/C21 -> 0.099889816 | D22: =D18/D21 -> 0.11059077 | E22: =E18/E21 -> 0.10508502
B25: 3. MAJOR PROJECTS & CAPEX CATEGORIZATION
B26: CapEx Category | C26: Major Projects Identified | D26: Strategic Purpose
B27: Diversification (New Markets/Products) | C27: Saudi Aramco Master Gas System EPC Project | D27: A US$ 900 million gas pipeline network in Saudi Arabia, representing a landmark global expansion into high-value Oil & Gas infrastructure.
B28: Expansion (Same Line) | C28: Water Supply (Jal Jeevan Mission) & T&D Expansion | D28: Large-scale domestic infrastructure involving pipelines and treatment plants, serving as a core revenue driver for the company’s Water segment.
B29: Expansion (Same Line) | C29: Global HVDC Power Transmission Links | D29: Technically complex high-voltage projects in international markets, establishing KPIL as a leader in advanced renewable energy integration and grid modernization.
B30: Expansion (Same Line) | C30: Underground and Elevated Metro Projects | D30: Construction of metro rail systems across major Indian cities, leveraging specialized civil engineering and tunneling capabilities to enhance urban connectivity.
B31: R&D and Intangibles | C31: Design Centre of Excellence (DCOE) | D31: A strategic investment in digital twin and 3D modeling technology to improve project efficiency and reduce execution risks through engineering innovation.
B33: 4. CAPEX ANALYSIS
B34: FY 23 | C34: Expansion of Core Segments: CapEx was driven primarily by massive equipment deployment and capacity building for the Jal Jeevan Mission (Water Supply) and domestic Power T&D projects to fulfill the growing domestic order book.
B35: FY 24 | C35: Rationalization & Diversification: The year featured negative net CapEx due to the strategic sale of ₹775 Cr in non-core assets. The gross spending was redirected toward diversification, acquiring specialized heavy machinery for new Underground Metro projects and early-stage requirements for Middle East oil & gas contracts.
B36: FY 25 | C36: High-Complexity Global Scale-Up & R&D: A major surge in CapEx was driven by the execution of the landmark US$ 900MILLION Saudi Aramco EPC Pipeline and global HVDC transmission links. Capital was also invested in R&D and digital engineering through the Design Centre of Excellence (DCOE).
B39: 5. MAJOR SOURCES OF CAPITAL FOR CAPEX
B40: Funding Source | C40: Application to CapEx
B41: Internal Accruals (CFO) | C41: Routine 'Replacement' and 'R&D' CapEx are funded purely through operations.
B42: Asset Monetization (Equity Raising QIP) | C42: The Rs 1,000 Cr QIP funded the 'Expansion' CapEx into Saudi Arabia without adding debt.

Sheet KPIL - Corporate Finance (C)
B1: KALPATARU PROJECTS INTERNATIONAL LIMITED
B2: PART II- CORPORATE FINANCE
B4: C. Capital Structure Analysis
B7: Quarterly Capital Structure Table | G7: Capital Structure
B8: Quarter | C8: Revenue | D8: Ebitda | E8: Net Profit | G8: Year | H8: Total Debt | I8: Cash | J8: Net Debt | K8: Equity | L8: Debt/Equity | M8: Debt/Capital
B9: Q1 FY23 | C9: 3667 | D9: 317 | E9: 88 | G9: FY23 | H9: ='KPIL - BALANCE SHEET'!D49+'KPIL - BALANCE SHEET'!D50+'KPIL - BALANCE SHEET'!D60+'KPIL - BALANCE SHEET'!D61 -> 3786.13 | I9: ='KPIL - BALANCE SHEET'!D27 -> 956.43 | J9: =H9-I9 -> 2829.7 | K9: ='KPIL - BALANCE SHEET'!D45 -> 4693.86 | L9: =H9/K9 -> 0.80661332 | M9: =H9/(H9+K9) -> 0.44647812
B10: Q2 FY23 | C10: 3798 | D10: 354 | E10: 98 | G10: FY24 | H10: ='KPIL - BALANCE SHEET'!E49+'KPIL - BALANCE SHEET'!E50+'KPIL - BALANCE SHEET'!E60+'KPIL - BALANCE SHEET'!E61 -> 4008.2 | I10: ='KPIL - BALANCE SHEET'!E27 -> 1009.33 | J10: =H10-I10 -> 2998.87 | K10: ='KPIL - BALANCE SHEET'!E45 -> 5112.81 | L10: =H10/K10 -> 0.78395246 | M10: =H10/(H10+K10) -> 0.43944695
B11: Q3 FY23 | C11: 4004 | D11: 376 | E11: 109 | G11: FY25 | H11: ='KPIL - BALANCE SHEET'!F49+'KPIL - BALANCE SHEET'!F50+'KPIL - BALANCE SHEET'!F60+'KPIL - BALANCE SHEET'!F61 -> 4313.51 | I11: ='KPIL - BALANCE SHEET'!F27 -> 1601.69 | J11: =H11-I11 -> 2711.82 | K11: ='KPIL - BALANCE SHEET'!F45 -> 6468.86 | L11: =H11/K11 -> 0.66681146 | M11: =H11/(H11+K11) -> 0.40005212
B12: Q4 FY23 | C12: 4882 | D12: 454 | E12: 140
B13: Q1 FY24 | C13: 4241 | D13: 400 | E13: 113 | G13: Cash Flow vs Capex
B14: Q2 FY24 | C14: 4518.44 | D14: 382.93 | E14: 89.89 | G14: Year | H14: CFO | I14: CapEx | J14: CFO/CapEx | K14: Free Cash Flow
B15: Q3 FY24 | C15: 4895.82 | D15: 437.35 | E15: 144.07 | G15: FY23 | H15: ='KPIL -CF STATEMENT'!C13 -> 550 | I15: =ABS('KPIL - Corporate Finance (B)'!C10) -> 365.5 | J15: =H15/I15 -> 1.504788 | K15: =H15-I15 -> 184.5
B16: Q4 FY24 | C16: 5971.27 | D16: 472.27 | E16: 168.68 | G16: FY24 | H16: ='KPIL -CF STATEMENT'!D13 -> 950 | I16: =ABS('KPIL - Corporate Finance (B)'!D10) -> 229.8 | J16: =H16/I16 -> 4.1340296 | K16: =H16-I16 -> 720.2
B17: Q1 FY25 | C17: 4586.6 | D17: 300.79 | E17: 83.95 | G17: FY25 | H17: ='KPIL -CF STATEMENT'!E13 -> 1150 | I17: =ABS('KPIL - Corporate Finance (B)'!E10) -> 530 | J17: =H17/I17 -> 2.1698113 | K17: =H17-I17 -> 620
B18: Q2 FY25 | C18: 4929.93 | D18: 455.4 | E18: 125.56
B19: Q3 FY25 | C19: 5732.48 | D19: 489.49 | E19: 139.59 | K19: NOTE: CapEx has been adjusted to absolute values for ratio computation to ensure meaningful comparison across periods.
B20: Q4 FY25 | C20: 7066.77 | D20: 550.92 | E20: 218.17 | G20: Linkage Analysis
G21: Year | H21: CapEx | I21: Change in Debt
G22: FY23 | H22: =I15 -> 365.5 | I22: =H9-3837.78 -> -51.65
G23: FY24 | H23: =I16 -> 229.8 | I23: =H10-H9 -> 222.07 | K23: NOTE: CFO refers to cash flow from operating activities
G24: FY25 | H24: =I17 -> 530 | I24: =H11-H10 -> 305.31
B26: 1. Capital Structure Overview
B27: The capital structure of Kalpataru Projects International Ltd for FY2023 to FY2025 shows that the company is moderately and steadily increasing its leverage. From FY2023 to FY2025, total debt went up from ₹3786 Cr to ₹4313 Cr, and equity went up a lot from ₹4694 Cr to ₹6469 Cr. Because of this, the Debt/Equity ratio went down from 0.81x in FY2023 to 0.67x in FY2025. This shows that the balance sheet is getting stronger and the company is relying less on debt to pay for things.
B34: 2. Major Sources of Funding
B35: The company gets most of its money from a mix of debt and equity. Debt includes both short-term and long-term loans, while equity includes share capital, reserves, and interests that don't control the company. The growing equity base indicates robust internal accruals and retained earnings, whereas debt persists in facilitating capital-intensive operations characteristic of EPC firms.
B39: 3. Capital Structure Ratios Analysis
B40: The falling Debt/Equity ratio (0.81 → 0.78 → 0.67) and Debt/Capital ratio (0.45 → 0.44 → 0.40) show that the company is slowly paying off its debts. This shows that the company's finances are getting better and that it is moving toward a structure that is funded more by equity. The trend indicates prudent financial management and diminishing financial risk over time.
B44: 4. Link between Financing and CapEx
B45: The company's choices about how to pay for things are partly linked to how much it needs to spend on capital. In FY2025, CapEx goes up to ₹530 Cr, and debt goes up to ₹305 Cr. This shows that some of the money for expansion comes from loans. In FY2024, on the other hand, debt rose even though CapEx was reported to be negative (meaning that the company made more money from selling assets than it spent on investments). This suggests that the company needed money for other operational or investment needs. In FY2023, CapEx was paid for without taking on more debt, as shown by a drop in borrowings. In general, there is a relationship between CapEx and financing, but it is not always clear, which suggests that the company uses both internal and external funding strategies.
B49: 5. CFO vs CapEx
B50: The company's operating cash flows are always higher than what it needs to spend on capital. The CFO/CapEx ratios are above 1 in FY2023 and FY2025, which means that the company has enough cash coming in to pay for investments. In FY2024, the negative CapEx shows that investing activities brought in more money than they spent, so the ratio doesn't mean anything. Overall, the company's ability to pay for its capital expenditures with its own money is shown by the strong growth in operating cash flows.
B54: 6. Free Cash Flow Analysis | I54: 7. Final Conclusion
B55: Over the period, free cash flow has been going up steadily, going from ₹184.5 Cr in FY2023 to ₹620 Cr in FY2025. The very high free cash flow in FY2024 is due to negative CapEx, which shows net inflows from investing activities instead of normal capital expenditures. Aside from this one-time event, the company has consistently increased its free cash flow, which shows that its operations are becoming more efficient and its finances are becoming more flexible. | I55: In general, the company has a balanced and improving capital structure with a low level of debt. Debt is used to help the business grow, but the falling leverage ratios show that the business is becoming more financially stable. The company's operating cash flows are strong and usually enough to pay for capital expenses, which means it doesn't have to rely on outside financing as much. The fact that CapEx is negative in FY2024 suggests that the company should either sell off some of its assets or make changes to its investments. Overall, the company has a financing strategy that will last because it makes a lot of money on its own.

Sheet KPIL - Corporate Finance (D)
B1: KALPATARU PROJECTS INTERNATIONAL Ltd
B3: PART II- CORPORATE FINANCE
B5: D. WACC and Growth Rate Estimation
B8: COST OF EQUITY CALCULATION | D8: SOURCE
B9: Risk Free Rate | C9: 0.071 | D9: RBI Rate
B10: Beta | C10: 0.85 | D10: MoneyControl
B11: Market Risk Premium | C11: 0.0708 | D11: Avearge Equity Risk Premium for Indian Market
B12: Cost of Equity | C12: =C9 + C10*C11 -> 0.13118 | D12: Using CAPM : Risk Free Rate + Beta*Market Risk Premium
B15: COST OF DEBT CALCULATION | D15: SOURCE
B16: Interest Expense | C16: ='KPIL - P&L STATEMENT'!E13 -> 576.53 | D16: Annual Report
B17: Total Borrowings | C17: ='KPIL - BALANCE SHEET'!F49+'KPIL - BALANCE SHEET'!F50+'KPIL - BALANCE SHEET'!F60+'KPIL - BALANCE SHEET'!F61 -> 4313.51 | D17: Annual Report
B18: Pre-Tax Cost of Debt | C18: =C16/C17 -> 0.13365681 | D18: Interest Expense/Borrowings
B19: Tax Rate | C19: ='KPIL - P&L STATEMENT'!E56/100 -> 0.3105615 | D19: Calculated in P&L Statement as Effective Tax Rate
B20: After-Tax Cost of Debt | C20: =C18*(1-C19) -> 0.092148153 | D20: Pre-Tax Cost of Debt * (1 - Tax Rate)
B23: WEIGHTS CALCULATION | C23: TOTAL | D23: WEIGHTS | E23: SOURCE
B24: Number of outstanding shares as on March 31, 2025 | C24: 170772546 | E24: Annual Report
B25: Price per share as on March 31, 2025 | C25: 974.5 | E25: NSE
B26: Market Value of Equity (in crore) | C26: =(C24*C25)/10000000 -> 16641.785 | D26: =C26/(C26+C27) -> 0.79415656
B27: Total Borrowings | C27: =C17 -> 4313.51 | D27: =C27/(C27+C26) -> 0.20584344
B29: Weighted Average Cost of Capital(WACC) | C29: =D26*C12 + D27*C20 -> 0.12314555 | D29: (Weight of Equity*Cost of Equity) + (Weight of Debt*After-Tax Cost of Debt) | Z29: `
B32: *Note: Items like "Trade Payables" (Total outstanding dues of micro/small/other enterprises) and "Other Financial Liabilities" have been excluded because these are generally operational in nature and do not carry an explicit interest rate in the same way debt does.
B34: SUSTAINABLE GROWTH RATE CALCULATION | D34: NOTE: The growth rate has been estimated using the sustainable growth rate model, calculated as the product of return on equity (ROE) and the retention ratio. This reflects the firm’s ability to grow using internally generated funds without altering its capital structure.
B35: ROE | C35: ='KPIL - P&L STATEMENT'!E27/'KPIL - BALANCE SHEET'!F45 -> 0.087692422
B36: DIVIDEND PAYOUT RATIO | C36: =ABS('KPIL -CF STATEMENT'!E26)/'KPIL - P&L STATEMENT'!E27 -> 0.23798191
B37: RETENTION RATIO | C37: =1-C36 -> 0.76201809
B38: GROWTH RATE | C38: =C36*C37 -> 0.18134652
B40: Lifecycle Stage: Late Growth / Transition-to-Maturity
B41: The company seems to be in the growth stage of its corporate lifecycle because its estimated sustainable growth rate is about 18.13%. A high growth rate means that the company is putting a lot of its profits back into the business and making enough money to support growth. The company's relatively high retention ratio backs this up even more, since it is putting reinvestment ahead of paying dividends. Also, the fact that revenues are going up, cash flows are getting better, and leverage is being kept under control, as seen in earlier analysis, shows that the company is in an expansion phase rather than a maturity phase.
B42: Sustained Top-Line Momentum (Sales): KPIL continues to scale like a growth-stage firm. It maintains a robust 10-year Revenue CAGR of 12% (with a 3-year CAGR of ~15%). This momentum is intact, evidenced by a 13.7% jump in FY25 and aggressive management targets of 20% for FY26. Bottom-Line Stabilization (Profit/EPS): While the historical 10-year PAT CAGR is an impressive 17%, recent short-term (3-year) net income growth has stabilized into the single digits. This reflects a business model maturing from explosive, early-stage profit expansion to predictable, steady-state cash generation.
B44: Degree of Operating Leverage
B45: Degree of Operating Leverage | C45: FY 2023-24 (INR Cr) | D45: FY 2024-25 (INR Cr) | E45: % Change
B46: Gross Revenue | C46: ='KPIL - P&L STATEMENT'!D5 -> 19626.43 | D46: ='KPIL - P&L STATEMENT'!E5 -> 22315.78 | E46: =(D46-C46)/C46 -> 0.13702696
B47: Normal PBIT (EBIT) | C47: ='KPIL - P&L STATEMENT'!D55 -> 1219.27 | D47: ='KPIL - P&L STATEMENT'!E55 -> 1399.33 | E47: =(D47-C47)/C47 -> 0.14767853
B49: DOL | C49: =E47/E46 -> 1.0777334 | D49: Calculated as the percentage change in EBIT divided by the percentage change in Sales.
B50: Interpretation: For every 1% increase in revenue, KPIL's operating profit increases by approximately 1.08%. This indicates a relatively low DOL at the consolidated level, suggesting that a significant portion of its costs are variable (typical for EPC businesses).
B52: Degree of Financial Leverage
B53: Metric | D53: FY 2024-25 (INR Cr)
B54: Normal PBIT (EBIT) | D54: =D47 -> 1399.33
B55: Profit Before Tax (PBT) | D55: ='KPIL - P&L STATEMENT'!E22 -> 822.8
B57: DFL | C57: =D54/D55 -> 1.7006928 | D57: Calculated as EBIT / PBT
...

Sheet Data Collection & References
B2: DATA | G2: SOURCE
B3: WEEKLY CLOSING PRICE FOR COMPANY 1 (NTPC Ltd) AND NIFTY 50 | G3: https://www.nseindia.com/get-quote/equity/NTPC/NTPC-Limited , https://finance.yahoo.com/quote/%5ENSEI/history/?period1=1682640000&period2=1775779200&frequency=1wk
B4: BOND DATA FOR ISIN: INE733E07JW2 | G4: https://www.indiabonds.com/bond-directory/INE733E07JW2-ntpc-limited/
B5: DEBT TO EQUITY RATIO FOR NTPC: CALCULATED FROM TOTAL DEBT AND EQUITY TAKEN FROM | G5: https://finance.yahoo.com/quote/NTPC.NS/balance-sheet/
B7: TAX RATE FOR NTPC LTD: CALCULATED FROM TOTAL DEBT AND EQUITY TAKEN FROM | G7: https://finance.yahoo.com/quote/NTPC.NS/financials/
B8: COMPANY 2 (KALPATARU PROJECTS INTERNATIONAL Ltd) CONSOLIDATED BALANCE SHEET, P&L STATEMENT AND CASH FLOW STATEMENT | G8: https://kalpataruprojects.com/investors/financials/annual-reports/annual-reports
B12: NOTE: FOR THE CORPORATE FINANCE ANALYSIS OF KPIL (COMPANY 2) WE HAVE TAKEN ANNUAL REPORTS FOR FY 2022-23, FY 2023-24, AND FY 2024-25 AS THEY HAVE NOT UPLOADED THE ANNUAL REPORTS FOR THE YEAR 2025-26.
